Workbook

Sheet RINGKASAN
A1: DAFTAR REKOMTEK/PERTEK PERIZINAN/NON PERIZINAN USAHA PENYEDIAAN TENAGA LISTRIK UNTUK KEPENTINGAN SENDIRI TAHUN 2022 PROVINSI KALIMANTAN TIMUR
A3: No. | B3: Kota/Kabupaten | C3: Jumlah Rekomtek | E3: Jumlah Kapasitas (kVA)
C4: IUPTLS | D4: SKTP
A5: 1 | B5: 2 | C5: 3 | D5: 4 | E5: 5
A6: 1 | B6: Samarinda | C6: =SAMARINDA!H29 -> 6 | D6: =SAMARINDA!H30 -> 7 | E6: =SAMARINDA!P29 -> 14774.5
A7: 2 | B7: Balikpapan | C7: =BALIKPAPAN!H31 -> 10 | D7: =BALIKPAPAN!H32 -> 11 | E7: =BALIKPAPAN!P31 -> 18223
A8: 3 | B8: Kutai Kartanegara | C8: =KUKAR!H61 -> 12 | D8: =KUKAR!H62 -> 3 | E8: =KUKAR!P61 -> 41971.9
A9: 4 | B9: Kutai Timur | C9: =KUTIM!H31 -> 4 | D9: =KUTIM!H32 -> 4 | E9: =KUTIM!P31 -> 10702.5
A10: 5 | B10: Kutai Barat | C10: =KUBAR!H17 -> 3 | D10: =KUBAR!H18 -> 0 | E10: =KUBAR!P17 -> 11170
A11: 6 | B11: Paser | C11: =PASER!H19 -> 3 | D11: =PASER!H20 -> 0 | E11: =PASER!P19 -> 13110
A12: 7 | B12: Penajam Paser Utara | C12: =PPU!H14 -> 1 | D12: =PPU!H15 -> 0 | E12: =PPU!P14 -> 880
A13: 8 | B13: Bontang | C13: =BONTANG!H15 -> 2 | D13: =BONTANG!H16 -> 0 | E13: =BONTANG!P15 -> 7891.04
A14: 9 | B14: Berau | C14: =BERAU!H33 -> 6 | D14: =BERAU!H34 -> 3 | E14: =BERAU!P33 -> 25703.36
A15: 10 | B15: Mahakam Ulu | C15: =MAHULU!H10 -> 0 | D15: =MAHULU!H11 -> 0 | E15: =MAHULU!P10 -> 0
B16: Total | C16: =SUM(Table11[3])-1 -> 46 | D16: =SUM(Table11[4]) -> 28 | E16: =SUM(Table11[5])&" kVA" -> 144426.3 kVA
B17: Total Rekomtek/Pertek | C17: =SUM(C16:D16) -> 74
B18: *Jumlah Rekomtek IUPTLS dikurangi 1, karena lokasi pembangkit pada Rekomtek nomor 671.12/1747/I-KTL/2022 berlaku lintas kabupaten di Kukar dan Kutim.

Sheet SAMARINDA
A1: DAFTAR REKOMTEK/PERTEK PERIZINAN/NON PERIZINAN USAHA PENYEDIAAN TENAGA LISTRIK UNTUK KEPENTINGAN SENDIRI TAHUN 2022 KOTA SAMARINDA
A3: No. | B3: ID | C3: Data Pemohon/Pelaku Usaha | E3: Data Perizinan/Non Perizinan | L3: Data Pembangkit Listrik | S3: Catatan
C4: Nama | D4: Kontak | E4: Jenis | F4: No. Pengajuan | G4: No. Surat Keluar (Rekomtek/Pertek) | H4: Tanggal | I4: No. Surat Izin Terbit | J4: Tanggal Terbit | K4: Tanggal Akhir | L4: Lokasi | M4: Titik Koordinat | N4: Jumlah | O4: Kapasitas | P4: Total Kapasitas (kVA) | Q4: Jenis | R4: Sifat Penggunaan
A5: 1 | B5: 2 | C5: 3 | D5: 4 | E5: 5 | F5: 6 | G5: 7 | H5: 8 | I5: 9 | J5: 10 | K5: 11 | L5: 12 | M5: 13 | N5: 14 | O5: 15 | P5: 16 (14*15) | Q5: 17 | R5: 18 | S5: 19
A6: =IF($C6<>"", SUBTOTAL(103,$C$6:C6), "") -> 1 | B6: 1 | C6: PT. ASTRA INTERNATIONAL Tbk. TOYOTA - AUTO 2000 | E6: SKTP | F6: 503/188/DPMPTSP-IV/I/2022; 598464 | G6: 671.12/374/I-KTL/2022 | H6: 44608 | I6: 503/0138/SKTP/DPMPTSP/III/2022 | J6: 44627 | L6: Jl. Wahid Hasyim RT. 28, Kelurahan Sempaja Selatan, Kecamatan Samarinda Utara, Kota Samarinda | M6: S : 0°27'22.19" T : 117°9'13.2" | N6: 1 | O6: 400 | P6: =Table13[[#This Row],[14]]*Table13[[#This Row],[15]] -> 400 | Q6: PLTD | R6: DARURAT
A7: =IF($C7<>"", SUBTOTAL(103,$C$6:C7), "") -> 2 | B7: 2 | C7: PT. PAULA JAYA | E7: SKTP | F7: 503/236.2/DPMPTSP-IV/II/2022; 37D5B3 | G7: 671.12/448/I-KTL/2022 | H7: 44594 | I7: 503/0157/SKTP/DPMPTSP/III/2022 | J7: 44634 | L7: Jl. Sultan Sulaiman, Kelurahan Sambutan, Kecamatan Sambutan, Kota Samarinda | M7: S : 0°31'28" T : 117°12'56.82" | N7: 1 | O7: 112.5 | P7: =Table13[[#This Row],[14]]*Table13[[#This Row],[15]] -> 112.5 | Q7: PLTD | R7: DARURAT
A8: =IF($C8<>"", SUBTOTAL(103,$C$6:C8), "") -> 3 | B8: 3 | C8: RSUD A.W. SJAHRANIE | E8: IUPTLS | F8: I-202203170655447196705 | G8: 671.12/643/I-KTL/2022 | H8: 44655 | I8: 022000526180300020003 | J8: 44656 | K8: 46482 | L8: Jl. Palang Merah Indonesia No. 01, Kelurahan Sidodadi, Kecamatan Samarinda Ulu, Kota Samarinda | M8: S : 0°28'44.93" T : 117°8'36.16" | N8: 4 | O8: 1250 | P8: =Table13[[#This Row],[14]]*Table13[[#This Row],[15]] -> 5000 | Q8: PLTD | R8: DARURAT
A9: =IF($C9<>"", SUBTOTAL(103,$C$6:C9), "") -> 4 | B9: 4 | C9: PT. TRAKINDO UTAMA | E9: IUPTLS | F9: I-202203280926075365997 | G9: 671.12/941/I-KTL/2022 | H9: 44725 | I9: 812010785390500080093 | J9: 44753 | K9: 46579 | L9: Jl. Cipto Mangunkusumo, Kelurahan Sengkotek, Kecamatan Loa Janan Ilir, Kota Samarinda | M9: S : 0°33'3.54" T : 117°5'18.68" | N9: 1 | O9: 725 | P9: =Table13[[#This Row],[14]]*Table13[[#This Row],[15]] -> 725 | Q9: PLTD | R9: DARURAT
A10: =IF($C10<>"", SUBTOTAL(103,$C$6:C10), "") -> 5 | B10: 5 | C10: PT. CAHAYA SAMTRACO UTAMA | E10: IUPTLS | F10: I-202204052331084079482 | G10: 671.12/977/I-KTL/2022 | H10: 44733 | I10: 912000494092100020001 | J10: 44760 | K10: 46586 | L10: Jl. Ekonomi RT. 14, Kelurahan Loa Buah, Kecamatan Sungai Kunjang, Kota Samarinda | M10: S : 0°33'45.19" T : 117°4'47.84" | N10: 3 | O10: 288 | P10: =Table13[[#This Row],[14]]*Table13[[#This Row],[15]] -> 864 | Q10: PLTD | R10: UTAMA DAN CADANGAN
A11: =IF($C11<>"", SUBTOTAL(103,$C$6:C11), "") | B11: =B10 -> 5 | N11: 2 | O11: 500 | P11: =Table13[[#This Row],[14]]*Table13[[#This Row],[15]] -> 1000 | Q11: PLTD
A12: =IF($C12<>"", SUBTOTAL(103,$C$6:C12), "") | B12: =B11 -> 5 | N12: 1 | O12: 590 | P12: =Table13[[#This Row],[14]]*Table13[[#This Row],[15]] -> 590 | Q12: PLTD
A13: =IF($C13<>"", SUBTOTAL(103,$C$6:C13), "") -> 6 | B13: 6 | C13: PT. TRIBHAKTI INSPEKTAMA | E13: SKTP | F13: 503/684/DPMPTSP-IV/V/2022; 39881B | G13: 671.12/978/I-KTL/2022 | H13: 44733 | I13: 503/0247/SKTP/DPMPTSP/VI/2022 | J13: 44740 | L13: Jl. APT Pranoto No. 89, Kelurahan Sungai Keledang, Kecamatan Samarinda Seberang, Kota Samarinda 75131 | M13: S : 0°31'36.96690" T : 117°7'49.21940" | N13: 1 | O13: 100 | P13: =Table13[[#This Row],[14]]*Table13[[#This Row],[15]] -> 100 | Q13: PLTD | R13: DARURAT
A14: =IF($C14<>"", SUBTOTAL(103,$C$6:C14), "") -> 7 | B14: 7 | C14: PT. BCA KCU (Samarinda) | E14: SKTP | F14: 503/1082/DPMPTSP-IV/VIII/2022; B98E81 | G14: 671.12/1490/I-KTL/2022 | H14: 44826 | I14: 503/0322/SKTP/DPMPTSP/X/2022 | J14: 44838 | L14: Jl. Jendral Sudirman No. 30, Kelurahan Pasar Pagi, Kecamatan Samarinda Kota, Kota Samarinda | M14: S : 0°30'8.02” T : 117°8’39.92” | N14: 1 | O14: 300 | P14: =Table13[[#This Row],[14]]*Table13[[#This Row],[15]] -> 300 | Q14: PLTD | R14: DARURAT
A15: =IF($C15<>"", SUBTOTAL(103,$C$6:C15), "") -> 8 | B15: 8 | C15: Kantor Perwakilan BANK INDONESIA Provinsi Kalimantan Timur | E15: SKTP | F15: 503/1171/DPMPTSP-IV/VIII/2022; 8D74B2 | G15: 671.12/1541/I-KTL/2022 | H15: 44834 | I15: 503/0328/SKTP/DPMPTSP/X/2022 | J15: 44846 | L15: Jl. Basuki Rahmat No.15 Kota Samarinda | M15: 0˚29’45,72”S 117˚8’45,76”T | N15: 1 | O15: 11 | P15: =Table13[[#This Row],[14]]*Table13[[#This Row],[15]] -> 11 | Q15: PLTD | R15: DARURAT
A16: =IF($C16<>"", SUBTOTAL(103,$C$6:C16), "") | B16: =B15 -> 8 | F16: 503/1172/DPMPTSP-IV/VIII/2022 | L16: Jl. Seruni No.04 Kota Samarinda | M16: 0˚29’44,37”S 117˚8’47,3”T | N16: 1 | O16: 11 | P16: =Table13[[#This Row],[14]]*Table13[[#This Row],[15]] -> 11 | Q16: PLTD | R16: DARURAT
A17: =IF($C17<>"", SUBTOTAL(103,$C$6:C17), "") | B17: =B16 -> 8 | F17: 503/1173/DPMPTSP-IV/VIII/2022 | L17: Jl. Seruni No.04 Kota Samarinda | M17: 0˚29’43,42”S 117˚8’44,9”T | N17: 1 | O17: 10 | P17: =Table13[[#This Row],[14]]*Table13[[#This Row],[15]] -> 10 | Q17: PLTD | R17: DARURAT
A18: =IF($C18<>"", SUBTOTAL(103,$C$6:C18), "") | B18: =B17 -> 8 | F18: 503/1174/DPMPTSP-IV/VIII/2022 | L18: Jl. Basuki Rahmat No.07 Kota Samarinda | M18: 0˚29’47,34”S 117˚8’44,18”T | N18: 1 | O18: 11 | P18: =Table13[[#This Row],[14]]*Table13[[#This Row],[15]] -> 11 | Q18: PLTD | R18: DARURAT
A19: =IF($C19<>"", SUBTOTAL(103,$C$6:C19), "") -> 9 | B19: 9 | C19: PT. INTERASIONAL PRIMA COAL | E19: SKTP | F19: 503/1187/DPMPTSP-IV/VIII/2022; 0055AB | G19: 671.12/1748/I-KTL/2022 | H19: 44862 | I19: 503/0377/SKTP/DPMPTSP/XI/2022 | J19: 44887 | L19: Kelurahan Bantuas, Kecamatan Palaran, Kota Samarinda | M19: S : 0°37’55.74” T : 117°14’15.21” | N19: 2 | O19: 200 | P19: =Table13[[#This Row],[14]]*Table13[[#This Row],[15]] -> 400 | Q19: PLTD | R19: UTAMA
A20: =IF($C20<>"", SUBTOTAL(103,$C$6:C20), "") | B20: =B19 -> 9 | M20: S : 0°38’29.2” T : 117°11’8.18” | N20: 1 | O20: 15 | P20: =Table13[[#This Row],[14]]*Table13[[#This Row],[15]] -> 15 | Q20: PLTD | R20: UTAMA
A21: =IF($C21<>"", SUBTOTAL(103,$C$6:C21), "") -> 10 | B21: 10 | C21: PT. SAMARINDA CENTRAL INDONESIA (Aston Hotel & Convention Hall) | E21: IUPTLS | F21: I-202209301427163501556 | G21: 671.12/1877/I-KTL/2022 | H21: 44875 | I21: 912020963266700080004 | J21: 44879 | K21: 46705 | L21: Jl. P. Hidayatullah, Kel. Pelabuhan, Kec. Samarinda Kota, Kota Samarinda | M21: S : 0°30’7,48” T : 117°9’17,53” | N21: 1 | O21: 1675 | P21: =Table13[[#This Row],[14]]*Table13[[#This Row],[15]] -> 1675 | Q21: PLTD | R21: DARURAT
A22: =IF($C22<>"", SUBTOTAL(103,$C$6:C22), "") | B22: =B21 -> 10 | N22: 1 | O22: 1500 | P22: =Table13[[#This Row],[14]]*Table13[[#This Row],[15]] -> 1500 | Q22: PLTD | R22: DARURAT
A23: =IF($C23<>"", SUBTOTAL(103,$C$6:C23), "") -> 11 | B23: 11 | C23: PT. SARANA INDAH PERKASA (Hotel Midtown) | E23: IUPTLS | F23: I-202210201338197386762 | G23: 671.12/1983/I-KTL/2022 | H23: 44889 | I23: 912000447072400000003 | J23: 44895 | K23: 46721 | L23: Jl. Hasan Basri No. 58, Kelurahan Bandara, Kecamatan Sungai Pinang, Kota Samarinda | M23: S : 0°28’49.94” T : 117°9’12.85” | N23: 1 | O23: 500 | P23: =Table13[[#This Row],[14]]*Table13[[#This Row],[15]] -> 500 | Q23: PLTD | R23: DARURAT
A24: =IF($C24<>"", SUBTOTAL(103,$C$6:C24), "") | B24: =B23 -> 11 | N24: 1 | O24: 550 | P24: =Table13[[#This Row],[14]]*Table13[[#This Row],[15]] -> 550 | Q24: PLTD | R24: DARURAT
A25: =IF($C25<>"", SUBTOTAL(103,$C$6:C25), "") -> 12 | B25: 12 | C25: PT. LOTTE SHOPPING INDONESIA | E25: IUPTLS | F25: I-202211141307230696079 | G25: 671.12/2092/I-KTL/2022 | H25: 44900 | I25: 812010381321700080034 | J25: 44909 | K25: 46735 | L25: Kelurahan Air Hitam, Kecamatan Samarinda Ulu, Kota Samarinda | M25: S : 0°28’24.9” T : 117°7’58.1” | N25: 2 | O25: 400 | P25: =Table13[[#This Row],[14]]*Table13[[#This Row],[15]] -> 800 | Q25: PLTD | R25: DARURAT
A26: =IF($C26<>"", SUBTOTAL(103,$C$6:C26), "") -> 13 | B26: 13 | C26: PT. GRAND SAWIT HOTEL | E26: SKTP | F26: 9B980D | G26: 671.12/2226/I-KTL/2022 | H26: 44915 | I26: 503/0428/SKTP/DPMPTSP/XII/2022 | J26: 44924 | L26: Jl. K.H. Abdurrasyid No. 34A (Eks Jl. Basuki Rahmat) Kelurahan Bugis, Kecamatan Samarinda Kota, Kota Samarinda | M26: 0°29’ 49,53”S 117°8’43,66’’T | N26: 1 | O26: 200 | P26: =Table13[[#This Row],[14]]*Table13[[#This Row],[15]] -> 200 | Q26: PLTD | R26: DARURAT | S26: Data terdapat pada SKTP terbit, pertek tidak ada salinan digital.
G29: Jumlah Rekomtek IUPTLS | H29: =COUNTIF($E$6:$E$26,"IUPTLS") -> 6 | N29: Total Kapasitas (kVA) | P29: =SUM($P$6:$P26) -> 14774.5
G30: Jumlah Pertek SKTP | H30: =COUNTIF($E$6:$E$26,"SKTP") -> 7
G31: Jumlah Total | H31: =SUM(H29:H30) -> 13

Sheet BALIKPAPAN
A1: DAFTAR REKOMTEK/PERTEK PERIZINAN/NON PERIZINAN USAHA PENYEDIAAN TENAGA LISTRIK UNTUK KEPENTINGAN SENDIRI TAHUN 2022 KOTA BALIKPAPAN
A3: No. | B3: ID | C3: Data Pemohon/Pelaku Usaha | E3: Data Perizinan/Non Perizinan | L3: Data Pembangkit Listrik | S3: Catatan
C4: Nama | D4: Kontak | E4: Jenis | F4: No. Pengajuan | G4: No. Surat Keluar (Rekomtek/Pertek) | H4: Tanggal | I4: No. Surat Izin Terbit | J4: Tanggal Terbit | K4: Tanggal Akhir | L4: Lokasi | M4: Titik Koordinat | N4: Jumlah | O4: Kapasitas | P4: Total Kapasitas (kVA) | Q4: Jenis | R4: Sifat Penggunaan
A5: 1 | B5: 2 | C5: 3 | D5: 4 | E5: 5 | F5: 6 | G5: 7 | H5: 8 | I5: 9 | J5: 10 | K5: 11 | L5: 12 | M5: 13 | N5: 14 | O5: 15 | P5: 16 (14*15) | Q5: 17 | R5: 18 | S5: 19
A6: =IF($C6<>"", SUBTOTAL(103,$C$6:C6), "") -> 1 | B6: 1 | C6: PT. HEXINDO ADIPERKASA Tbk. | E6: IUPTLS | F6: I-202202151537426258732 | G6: 671.12/447/I-KTL/2022 | H6: 44622 | I6: 812010584180600040003 | J6: 44629 | K6: 46455 | L6: Jl. Mulawarman RT. 52, No. 99 Kelurahan Manggar, Kecamatan Balikpapan Timur, Kota Balikpapan | M6: S : 0°44'32.5288" T : 119°120'5.5859" | N6: 1 | O6: 810 | P6: 810 | Q6: PLTD | R6: DARURAT
A7: =IF($C7<>"", SUBTOTAL(103,$C$6:C7), "") -> 2 | B7: 2 | C7: PT. PANDEGA CITRANIAGA | E7: IUPTLS | F7: I-202201131621548256347 | G7: 671.12/449/I-KTL/2022 | H7: 44622 | I7: 912000223149100010001 | J7: 44718 | K7: =IF($E7="IUPTLS",IF(ISBLANK(J7), " ", DATE(YEAR(J7)+5,MONTH(J7),DAY(J7))),IF($E7="SKTP","","")) -> 46544 | L7: Jl. Jend. Sudirman No. 1 Kelurahan Klandasan Ilir, Kecamatan Balikpapan, Kota Balikpapan | M7: S : 1°16'41.41" T : 116°50'15.63" | N7: 2 | O7: 1675 | P7: =Table1[[#This Row],[15]]*Table1[[#This Row],[14]] -> 3350 | Q7: PLTD | R7: DARURAT
A8: =IF($C8<>"", SUBTOTAL(103,$C$6:C8), "") -> 3 | B8: 3 | C8: PT. LIEBHERR INDONESIA PERKASA | E8: IUPTLS | F8: I-202201141422016064457 | G8: 671.12/451/I-KTL/2022 | H8: 44622 | I8: 812000284275900030001 | J8: 44629 | K8: =IF($E8="IUPTLS",IF(ISBLANK(J8), " ", DATE(YEAR(J8)+5,MONTH(J8),DAY(J8))),IF($E8="SKTP","","")) -> 46455 | L8: Jl. Mulawarman No. 12, RT. 23, Kelurahan Manggar, Kecamatan Balikpapan Timur, Kota Balikpapan | M8: S : 1°14'26.53" T : 116°56'48.51" | N8: 2 | O8: 735 | P8: =Table1[[#This Row],[15]]*Table1[[#This Row],[14]] -> 1470 | Q8: PLTD | R8: DARURAT
A9: =IF($C9<>"", SUBTOTAL(103,$C$6:C9), "") -> 4 | B9: 4 | C9: PT. HEXINDO ADIPERKASA Tbk. | E9: SKTP | F9: 503/295/DPMPTSP-IV/II/2022; 1E3EA1 | G9: 671.12/544/I-KTL/2022 | H9: 44641 | I9: 503/0191/SKTP/DPMPTSP/IV/2022 | J9: 44655 | K9: =IF($E9="IUPTLS",IF(ISBLANK(J9), " ", DATE(YEAR(J9)+5,MONTH(J9),DAY(J9))),IF($E9="SKTP","","")) | L9: Jl. Mulawarman RT. 52, No. 99 Kelurahan Manggar, Kecamatan Balikpapan Timur, Kota Balikpapan | M9: S : 0°44'32.5288" T : 119°120'5.5859" | N9: 1 | O9: 400 | P9: =Table1[[#This Row],[15]]*Table1[[#This Row],[14]] -> 400 | Q9: PLTD | R9: DARURAT
A10: =IF($C10<>"", SUBTOTAL(103,$C$6:C10), "") -> 5 | B10: 5 | C10: PT. HASTA KREASIMANDIRI (Swiss-Belhotel) | E10: IUPTLS | F10: I-202202111409154082477 | G10: 671.12/584/I-KTL/2022 | H10: 44642 | I10: 912020854270100000001 | J10: 44649 | K10: =IF($E10="IUPTLS",IF(ISBLANK(J10), " ", DATE(YEAR(J10)+5,MONTH(J10),DAY(J10))),IF($E10="SKTP","","")) -> 46475 | L10: Jl. Jend. Sudirman Pasar Baru, Kelurahan Klandasan Ilir, Kecamatan Balikpapan Kota, Kota Balikpapan | M10: S : 1°16'42.5" T : 116°50'25.77" | N10: 1 | O10: 1250 | P10: =Table1[[#This Row],[15]]*Table1[[#This Row],[14]] -> 1250 | Q10: PLTD | R10: DARURAT
A11: =IF($C11<>"", SUBTOTAL(103,$C$6:C11), "") -> 6 | B11: 6 | C11: PT. ESTRELLA TIGA INDONESIA (Whiz Prime Hotel) | E11: SKTP | F11: 503/815/DPMPTSP-IV/VI/2022; 78346F | G11: 671.12/1118/I-KTL/2022 | H11: 44757 | I11: 503/0266/SKTP/DPMPTSP/VII/2022 | J11: 44769 | K11: =IF($E11="IUPTLS",IF(ISBLANK(J11), " ", DATE(YEAR(J11)+5,MONTH(J11),DAY(J11))),IF($E11="SKTP","","")) | L11: Jl. Jend. Sudirman No. 321, RT. 09, Kelurahan Damai, Kecamatan Balikpapan Kota, Kota Balikpapan 76114 | M11: S : 1°16'20.053" T : 116°51'8.280" | N11: 1 | O11: 500 | P11: =Table1[[#This Row],[15]]*Table1[[#This Row],[14]] -> 500 | Q11: PLTD | R11: DARURAT
A12: =IF($C12<>"", SUBTOTAL(103,$C$6:C12), "") -> 7 | B12: 7 | C12: PT. SINAR MAS WISESA | E12: IUPTLS | F12: I-202207220821451255062 | G12: 671.12/1481/I-KTL/2022 | H12: 44826 | I12: 912000987091700020004 | J12: 44844 | K12: =IF($E12="IUPTLS",IF(ISBLANK(J12), " ", DATE(YEAR(J12)+5,MONTH(J12),DAY(J12))),IF($E12="SKTP","","")) -> 46670 | L12: Jl. MT. Haryono, Kompleks Ruko Balikpapan Baru, Kota Balikpapan | M12: S : 1°14’37,14” T : 116°4’47,84” | N12: 2 | O12: 810 | P12: =Table1[[#This Row],[15]]*Table1[[#This Row],[14]] -> 1620 | Q12: PLTD | R12: DARURAT
A13: =IF($C13<>"", SUBTOTAL(103,$C$6:C13), "") | B13: =B12 -> 7 | K13: =IF($E13="IUPTLS",IF(ISBLANK(J13), " ", DATE(YEAR(J13)+5,MONTH(J13),DAY(J13))),IF($E13="SKTP","","")) | N13: 1 | O13: 410 | P13: =Table1[[#This Row],[15]]*Table1[[#This Row],[14]] -> 410 | Q13: PLTD | R13: DARURAT
A14: =IF($C14<>"", SUBTOTAL(103,$C$6:C14), "") -> 8 | B14: 8 | C14: PT. HANJAYA MANDALA SAMPOERNA Tbk. | E14: SKTP | F14: 503/1092/DPMPTSP-IV/VIII/2022; A6395E | G14: 671.12/1482/I-KTL/2022 | H14: 44826 | I14: 503/0319/SKTP/DPMPTSP/X/2022 | J14: 44838 | K14: =IF($E14="IUPTLS",IF(ISBLANK(J14), " ", DATE(YEAR(J14)+5,MONTH(J14),DAY(J14))),IF($E14="SKTP","","")) | L14: Jl. MT. Haryono No. 199 RT. 26, Kelurahan Sungai Nangka, Kecamatan Balikpapan Selatan, Kota Balikpapan | M14: S : 1°15’24.44” T : 116°52’10.22” | N14: 1 | O14: 100 | P14: =Table1[[#This Row],[15]]*Table1[[#This Row],[14]] -> 100 | Q14: PLTD | R14: DARURAT
A15: =IF($C15<>"", SUBTOTAL(103,$C$6:C15), "") -> 9 | B15: 9 | C15: PT. SANGGAR SARANA BAJA | E15: IUPTLS | F15: I-202208081631011433512 | G15: 671.12/1488/I-KTL/2022 | H15: 44826 | I15: 812011921150800330002 | J15: 44838 | K15: =IF($E15="IUPTLS",IF(ISBLANK(J15), " ", DATE(YEAR(J15)+5,MONTH(J15),DAY(J15))),IF($E15="SKTP","","")) -> 46664 | L15: Jl. Sultan Hasanuddin No. 08, Kelurahan Kariangau, Kecamatan Balikpapan Barat, Kota Balikpapan | M15: S : 1°12’9.37” T : 116°49’1.97” | N15: 1 | O15: 810 | P15: =Table1[[#This Row],[15]]*Table1[[#This Row],[14]] -> 810 | Q15: PLTD | R15: DARURAT
A16: =IF($C16<>"", SUBTOTAL(103,$C$6:C16), "") -> 10 | B16: 10 | C16: PT. PRIMAHOTEL MANAJEMEN INDONESIA | E16: SKTP | F16: 503/1040/DPMPTSP-IV/VIII/2022; 8D6F6A | G16: 671.12/1499/I-KTL/2022 | H16: 44826 | I16: 503/0313/SKTP/DPMPTSP/X/2022 | J16: 44838 | K16: =IF($E16="IUPTLS",IF(ISBLANK(J16), " ", DATE(YEAR(J16)+5,MONTH(J16),DAY(J16))),IF($E16="SKTP","","")) | L16: Jl. MT. Haryono No. 78, Kelurahan Damai, Kecamatan Balikpapan Kota, Kota Balikpapan | M16: S : 1°15'59.94” T : 116°51’27.44” | N16: 1 | O16: 410 | P16: =Table1[[#This Row],[15]]*Table1[[#This Row],[14]] -> 410 | Q16: PLTD | R16: DARURAT
A17: =IF($C17<>"", SUBTOTAL(103,$C$6:C17), "") -> 11 | B17: 11 | C17: PT. SERASI LOGISTICS INDONESIA | E17: SKTP | F17: 503/1083/DPMPTSP-IV/VIII/2022; C277F0 | G17: 671.12/1501/I-KTL/2022 | H17: 44827 | I17: 503/0323/SKTP/DPMPTSP/X/2022 | J17: 44838 | K17: =IF($E17="IUPTLS",IF(ISBLANK(J17), " ", DATE(YEAR(J17)+5,MONTH(J17),DAY(J17))),IF($E17="SKTP","","")) | L17: Komplek Pergudangan Golden Kariangau Jl. Sultan Hasanuddin No. 71 RT. 48, Kelurahan Karang Joang, Kecamatan Balikpapan Utara, Kota Balikpapan | M17: S : 1°10'30.09” T : 116°50’43.52” | N17: 1 | O17: 22 | P17: =Table1[[#This Row],[15]]*Table1[[#This Row],[14]] -> 22 | Q17: PLTD | R17: DARURAT
A18: =IF($C18<>"", SUBTOTAL(103,$C$6:C18), "") -> 12 | B18: 12 | C18: PT. PAMAPERSADA NUSANTARA (PAMA BPOP) | E18: IUPTLS | F18: I-202207290911423738502 | G18: 671.12/1502/I-KTL/2022 | H18: 44827 | I18: 812021106038900480073 | J18: 44838 | K18: =IF($E18="IUPTLS",IF(ISBLANK(J18), " ", DATE(YEAR(J18)+5,MONTH(J18),DAY(J18))),IF($E18="SKTP","","")) -> 46664 | L18: Jl. Mulawarman RT.39, Kelurahan Manggar Kecamatan Balikpapan Timur, Kota Balikpapan | M18: S : 1°13’30” T : 116°57’56” | N18: 3 | O18: 500 | P18: =Table1[[#This Row],[15]]*Table1[[#This Row],[14]] -> 1500 | Q18: PLTD | R18: DARURAT
A19: =IF($C19<>"", SUBTOTAL(103,$C$6:C19), "") -> 13 | B19: 13 | C19: PT. PAMAPERSADA NUSANTARA (PAMA ERKA) | E19: IUPTLS | F19: I-202207291611470175943 | G19: 671.12/1503/I-KTL/2022 | H19: 44827 | I19: 812021106038900490078 | J19: 44895 | K19: =IF($E19="IUPTLS",IF(ISBLANK(J19), " ", DATE(YEAR(J19)+5,MONTH(J19),DAY(J19))),IF($E19="SKTP","","")) -> 46721 | L19: Jl. Sultan Hasanudin, RT.14, Kelurahan Kariangau Kecamatan Balikpapan Barat, Kota Balikpapan | M19: S : 1°12’5.46115” T : 116°49’23.15517” | N19: 2 | O19: 500 | P19: =Table1[[#This Row],[15]]*Table1[[#This Row],[14]] -> 1000 | Q19: PLTD | R19: DARURAT
A20: =IF($C20<>"", SUBTOTAL(103,$C$6:C20), "") -> 14 | B20: 14 | C20: PT. PAMAPERSADA NUSANTARA (PAMA PSR) | E20: IUPTLS | F20: I-202208011528308164734 | G20: 671.12/1504/I-KTL/2022 | H20: 44827 | I20: 812021106038900480074 | J20: 44838 | K20: =IF($E20="IUPTLS",IF(ISBLANK(J20), " ", DATE(YEAR(J20)+5,MONTH(J20),DAY(J20))),IF($E20="SKTP","","")) -> 46664 | L20: Jl. Syarifuddin Yoes RT.01, Kelurahan Sepinggan Baru, Kecamatan Balikpapan Selatan, Kota Balikpapan | M20: S : 1°15’23” T : 116°54’14.20” | N20: 2 | O20: 350 | P20: =Table1[[#This Row],[15]]*Table1[[#This Row],[14]] -> 700 | Q20: PLTD | R20: DARURAT
A21: =IF($C21<>"", SUBTOTAL(103,$C$6:C21), "") -> 15 | B21: 15 | C21: PT. MIL PLATINUM BERSAUDARA | E21: IUPTLS | F21: I-202209090948329288237 | G21: 671.12/1542/I-KTL/2022 | H21: 44834 | I21: 912020834088600010001 | J21: 44846 | K21: =IF($E21="IUPTLS",IF(ISBLANK(J21), " ", DATE(YEAR(J21)+5,MONTH(J21),DAY(J21))),IF($E21="SKTP","","")) -> 46672 | L21: Jl. Soekarno -Hatta, No. 28 Kecamatan Balikpapan Utara, Kota Balikpapan | M21: 1°14’37,14”S 116°4’47,84”T | N21: 2 | O21: 800 | P21: =Table1[[#This Row],[15]]*Table1[[#This Row],[14]] -> 1600 | Q21: PLTD | R21: DARURAT
A22: =IF($C22<>"", SUBTOTAL(103,$C$6:C22), "") -> 16 | B22: 16 | C22: PT. ASTRA INTERNATIONAL Tbk. TOYOTA AUTO 2000 (MT Haryono - Perbaikan Bodi dan Cat) | E22: SKTP | F22: 503/1259.3/DPMPTSP-IV/IX/2022; 56C63E | G22: 671.12/1844/I-KTL/2022 | H22: 44874 | I22: 503/0378/SKTP/DPMPTSP/XI/2022 | J22: 44887 | K22: =IF($E22="IUPTLS",IF(ISBLANK(J22), " ", DATE(YEAR(J22)+5,MONTH(J22),DAY(J22))),IF($E22="SKTP","","")) | L22: Jl. MT. Haryono No. 67, RT 06 Kelurahan Damai Nangka, Kecamatan Balikpapan Selatan, Kota Balikpapan | M22: S : 1°15'28.93" T : 116°52'7.2" | N22: 1 | O22: 250 | P22: =Table1[[#This Row],[15]]*Table1[[#This Row],[14]] -> 250 | Q22: PLTD | R22: DARURAT
A23: =IF($C23<>"", SUBTOTAL(103,$C$6:C23), "") -> 17 | B23: 17 | C23: PT. ASTRA INTERNATIONAL Tbk. TOYOTA AUTO 2000 (MT Haryono - Penjualan Mobil) | E23: SKTP | F23: 503/1263/DPMPTSP-IV/IX/2022; FDF64A | G23: 671.12/1845/I-KTL/2022 | H23: 44874 | I23: 503/0379/SKTP/DPMPTSP/XI/2022 | J23: 44887 | K23: =IF($E23="IUPTLS",IF(ISBLANK(J23), " ", DATE(YEAR(J23)+5,MONTH(J23),DAY(J23))),IF($E23="SKTP","","")) | L23: Jl. MT. Haryono No. 188, RT 36 Kelurahan Damai Bahagia, Kecamatan Balikpapan Selatan, Kota Balikpapan | M23: S : 1°15'28.29" T : 116°52'9.24" | N23: 1 | O23: 150 | P23: =Table1[[#This Row],[15]]*Table1[[#This Row],[14]] -> 150 | Q23: PLTD | R23: DARURAT
A24: =IF($C24<>"", SUBTOTAL(103,$C$6:C24), "") -> 18 | B24: 18 | C24: PT. ASTRA INTERNATIONAL Tbk. TOYOTA AUTO 2000 (Jend. Sudirman) | E24: SKTP | F24: 503/1271.1/DPMPTSP-IV/IX/2022; 9D8E4E | G24: 671.12/1846/I-KTL/2022 | H24: 44874 | I24: 503/0387/SKTP/DPMPTSP/XI/2022 | J24: 44893 | K24: =IF($E24="IUPTLS",IF(ISBLANK(J24), " ", DATE(YEAR(J24)+5,MONTH(J24),DAY(J24))),IF($E24="SKTP","","")) | L24: Jl. Jend. Sudirman No. 29 RT. 35, Kelurahan Klandasan Ilir, Kecamatan Balikpapan Kota, Kota Balikpapan | M24: S : 1°16'27.53" T : 116°50'52.3" | N24: 1 | O24: 165 | P24: =Table1[[#This Row],[15]]*Table1[[#This Row],[14]] -> 165 | Q24: PLTD | R24: DARURAT
A25: =IF($C25<>"", SUBTOTAL(103,$C$6:C25), "") -> 19 | B25: 19 | C25: PT. THIESS CONTRACTORS INDONESIA | E25: SKTP | F25: C077F0 | G25: 671.12/1874/I-KTL/2022 | H25: 44875 | I25: 503/0380/SKTP/DPMPTSP/XI/2022 | J25: 44887 | K25: =IF($E25="IUPTLS",IF(ISBLANK(J25), " ", DATE(YEAR(J25)+5,MONTH(J25),DAY(J25))),IF($E25="SKTP","","")) | L25: Kelurahan Kariangau, Kecamatan Balikpapan Barat, Kota Balikpapan | M25: S : 1°11'58.79" T : 116°49'27.48" | N25: 1 | O25: 200 | P25: =Table1[[#This Row],[15]]*Table1[[#This Row],[14]] -> 200 | Q25: PLTD | R25: UTAMA
A26: =IF($C26<>"", SUBTOTAL(103,$C$6:C26), "") | B26: =B25 -> 19 | K26: =IF($E26="IUPTLS",IF(ISBLANK(J26), " ", DATE(YEAR(J26)+5,MONTH(J26),DAY(J26))),IF($E26="SKTP","","")) | N26: 1 | O26: 365 | P26: =Table1[[#This Row],[15]]*Table1[[#This Row],[14]] -> 365 | Q26: PLTD | R26: UTAMA
A27: =IF($C27<>"", SUBTOTAL(103,$C$6:C27), "") -> 20 | B27: 20 | C27: PT. SELARAS ANUGERAH SENTOSA | E27: SKTP | F27: FE2F0F | G27: 671.12/1876/I-KTL/2022 | H27: 44875 | I27: 503/0376/SKTP/DPMPTSP/XI/2022 | J27: 44887 | K27: =IF($E27="IUPTLS",IF(ISBLANK(J27), " ", DATE(YEAR(J27)+5,MONTH(J27),DAY(J27))),IF($E27="SKTP","","")) | L27: Kelurahan Sepinggan Raya, Kecamatan Balikpapan Selatan, Kota Balikpapan | M27: S : 1°15'45.33" T : 116°53'36.29" | N27: 1 | O27: 550 | P27: =Table1[[#This Row],[15]]*Table1[[#This Row],[14]] -> 550 | Q27: PLTD | R27: UTAMA
A28: =IF($C28<>"", SUBTOTAL(103,$C$6:C28), "") -> 21 | B28: 21 | C28: PT. SURYA NUSANTARA JAYA (Hotel Zurich Balikpapan) | E28: SKTP | F28: D85914 | G28: 671.12/2094/I-KTL/2022 | H28: 44900 | I28: 503/0422/SKTP/DPMPTSP/XII/2022 | J28: 44917 | K28: =IF($E28="IUPTLS",IF(ISBLANK(J28), " ", DATE(YEAR(J28)+5,MONTH(J28),DAY(J28))),IF($E28="SKTP","","")) | L28: Jl. Jend. Sudirman No. 81 RT. 04, Kelurahan Damai Bahagia, Kecamatan Balikpapan Selatan, Kota Balikpapan | M28: S : 1°16’13.86” T : 116°51’31.49” | N28: 1 | O28: 591 | P28: =Table1[[#This Row],[15]]*Table1[[#This Row],[14]] -> 591 | Q28: PLTD | R28: DARURAT
G31: Jumlah Rekomtek IUPTLS | H31: =COUNTIF($E$6:$E$28,"IUPTLS") -> 10 | N31: Total Kapasitas (kVA) | P31: =SUM($P$6:$P$28) -> 18223
G32: Jumlah Pertek SKTP | H32: =COUNTIF($E$6:$E$28,"SKTP") -> 11
G33: Jumlah Total | H33: =SUM(H31:H32) -> 21

Sheet KUKAR
A1: DAFTAR REKOMTEK/PERTEK PERIZINAN/NON PERIZINAN USAHA PENYEDIAAN TENAGA LISTRIK UNTUK KEPENTINGAN SENDIRI TAHUN 2022 KABUPATEN KUTAI KARTANEGARA
A3: No. | B3: ID | C3: Data Pemohon/Pelaku Usaha | E3: Data Perizinan/Non Perizinan | L3: Data Pembangkit Listrik | S3: Catatan
C4: Nama | D4: Kontak | E4: Jenis | F4: No. Pengajuan | G4: No. Surat Keluar (Rekomtek/Pertek) | H4: Tanggal | I4: No. Surat Izin Terbit | J4: Tanggal Terbit | K4: Tanggal Akhir | L4: Lokasi | M4: Titik Koordinat | N4: Jumlah | O4: Kapasitas | P4: Total Kapasitas (kVA) | Q4: Jenis | R4: Sifat Penggunaan
A5: 1 | B5: 2 | C5: 3 | D5: 4 | E5: 5 | F5: 6 | G5: 7 | H5: 8 | I5: 9 | J5: 10 | K5: 11 | L5: 12 | M5: 13 | N5: 14 | O5: 15 | P5: 16 (14*15) | Q5: 17 | R5: 18 | S5: 19
A6: =IF($C6<>"", SUBTOTAL(103,$C$6:C6), "") -> 1 | B6: 1 | C6: PT. INDUSTRI KELUARGA TIMUR | E6: SKTP | F6: 503/248/DPMPTSP-IV/II/2022; 9617FC | G6: 671.12/545/I-KTL/2022 | H6: 44641 | I6: 503/0192/SKTP/DPMPTSP/IV/2022 | J6: 44655 | K6: =IF($E6="IUPTLS",IF(ISBLANK(J6), " ", DATE(YEAR(J6)+5,MONTH(J6),DAY(J6))),IF($E6="SKTP","","")) | L6: Jl. Soekarno Hatta Km. 16, Dusun Tani Maju, Desa Batuah, Kecamatan Loa Janan, Kabupaten Kutai Kartanegara | M6: S : 0°40'18.68" T : 117°5'39.62" | N6: 1 | O6: 100 | P6: =Table14[[#This Row],[14]]*Table14[[#This Row],[15]] -> 100 | Q6: PLTD | R6: DARURAT
A7: =IF($C7<>"", SUBTOTAL(103,$C$6:C7), "") | B7: =B6 -> 1 | K7: =IF($E7="IUPTLS",IF(ISBLANK(J7), " ", DATE(YEAR(J7)+5,MONTH(J7),DAY(J7))),IF($E7="SKTP","","")) | N7: 1 | O7: 110 | P7: =Table14[[#This Row],[14]]*Table14[[#This Row],[15]] -> 110 | Q7: PLTD | R7: DARURAT
A8: =IF($C8<>"", SUBTOTAL(103,$C$6:C8), "") -> 2 | B8: 2 | C8: PT. JAPFA COMFEED INDONESIA Tbk. | E8: IUPTLS | F8: I-202201200948254988415 | G8: 671.12/642/I-KTL/2022 | H8: 44655 | I8: 812000478250500180072 | J8: 44656 | K8: =IF($E8="IUPTLS",IF(ISBLANK(J8), " ", DATE(YEAR(J8)+5,MONTH(J8),DAY(J8))),IF($E8="SKTP","","")) -> 46482 | L8: Desa Tani Bhakti, Kecamatan Loa Janan, Kabupaten Kutai Kartanegara | M8: S : 0°39'47.55" T : 117°6'31.08" | N8: 2 | O8: 377 | P8: =Table14[[#This Row],[14]]*Table14[[#This Row],[15]] -> 754 | Q8: PLTD | R8: DARURAT
A9: =IF($C9<>"", SUBTOTAL(103,$C$6:C9), "") | B9: =B8 -> 2 | K9: =IF($E9="IUPTLS",IF(ISBLANK(J9), " ", DATE(YEAR(J9)+5,MONTH(J9),DAY(J9))),IF($E9="SKTP","","")) | N9: 1 | O9: 380 | P9: =Table14[[#This Row],[14]]*Table14[[#This Row],[15]] -> 380 | Q9: PLTD | R9: DARURAT
A10: =IF($C10<>"", SUBTOTAL(103,$C$6:C10), "") -> 3 | B10: 3 | C10: PT. BUMI MAS AGRO | E10: IUPTLS | F10: I-202204010959360037495 | G10: 671.12/748/I-KTL/2022 | H10: 44677 | I10: 912000931098300020011 | J10: 44678 | K10: =IF($E10="IUPTLS",IF(ISBLANK(J10), " ", DATE(YEAR(J10)+5,MONTH(J10),DAY(J10))),IF($E10="SKTP","","")) -> 46504 | L10: Desa Marukangan, Kecamatan Sandaran, Kabupaten Kutai Kartanegara | M10: Lat : 0°53.168' Long : 118°24.113' | N10: 1 | O10: 2000 | P10: =Table14[[#This Row],[14]]*Table14[[#This Row],[15]] -> 2000 | Q10: PLTU | R10: UTAMA DAN CADANGAN
A11: =IF($C11<>"", SUBTOTAL(103,$C$6:C11), "") | B11: =B10 -> 3 | K11: =IF($E11="IUPTLS",IF(ISBLANK(J11), " ", DATE(YEAR(J11)+5,MONTH(J11),DAY(J11))),IF($E11="SKTP","","")) | M11: Lat : 0.865406° Long : 118.473778° | N11: 1 | O11: 1625 | P11: =Table14[[#This Row],[14]]*Table14[[#This Row],[15]] -> 1625 | Q11: PLTBG
A12: =IF($C12<>"", SUBTOTAL(103,$C$6:C12), "") | B12: =B11 -> 3 | K12: =IF($E12="IUPTLS",IF(ISBLANK(J12), " ", DATE(YEAR(J12)+5,MONTH(J12),DAY(J12))),IF($E12="SKTP","","")) | N12: 2 | O12: 729 | P12: =Table14[[#This Row],[14]]*Table14[[#This Row],[15]] -> 1458 | Q12: PLTD
A13: =IF($C13<>"", SUBTOTAL(103,$C$6:C13), "") | B13: =B12 -> 3 | K13: =IF($E13="IUPTLS",IF(ISBLANK(J13), " ", DATE(YEAR(J13)+5,MONTH(J13),DAY(J13))),IF($E13="SKTP","","")) | N13: 1 | O13: 330 | P13: =Table14[[#This Row],[14]]*Table14[[#This Row],[15]] -> 330 | Q13: PLTD
A14: =IF($C14<>"", SUBTOTAL(103,$C$6:C14), "") -> 4 | B14: 4 | C14: PT. BUKIT MAKMUR MANDIRI UTAMA (BUMA TABANG) | E14: IUPTLS | F14: I-202204052331084079482 | G14: 671.12/905/I-KTL/2022 | H14: 44718 | I14: 812020188155200110002 | J14: 44743 | K14: =IF($E14="IUPTLS",IF(ISBLANK(J14), " ", DATE(YEAR(J14)+5,MONTH(J14),DAY(J14))),IF($E14="SKTP","","")) -> 46569 | L14: Desa Senyiur, Kecamatan Muara Ancalong, Kabupaten Kutai Kartanegara | M14: U : 0°17'34109179" T : 116°34'23.681123" | N14: 2 | O14: 350 | P14: =Table14[[#This Row],[14]]*Table14[[#This Row],[15]] -> 700 | Q14: PLTD | R14: UTAMA DAN CADANGAN
A15: =IF($C15<>"", SUBTOTAL(103,$C$6:C15), "") | B15: =B14 -> 4 | K15: =IF($E15="IUPTLS",IF(ISBLANK(J15), " ", DATE(YEAR(J15)+5,MONTH(J15),DAY(J15))),IF($E15="SKTP","","")) | M15: U : 0°17'24599905" T : 116°34'50.080562" | N15: 2 | O15: 350 | P15: =Table14[[#This Row],[14]]*Table14[[#This Row],[15]] -> 700 | Q15: PLTD
A16: =IF($C16<>"", SUBTOTAL(103,$C$6:C16), "") -> 5 | B16: 5 | C16: PT. AGRI EASTBORNEO KENCACA | E16: IUPTLS | F16: I-202205310956166843177 | G16: 671.12/1011/I-KTL/2022 | H16: 44739 | I16: 812010490065400020001 | J16: 44753 | K16: =IF($E16="IUPTLS",IF(ISBLANK(J16), " ", DATE(YEAR(J16)+5,MONTH(J16),DAY(J16))),IF($E16="SKTP","","")) -> 46579 | L16: Site Plant PT. Agri Eastborneo Kencana, Desa Sedulung dan Desa Manamang, Kecamatan Muara Kaman, Kabupaten Kutai Kartanegara | M16: U : 0°7'8.4468" T : 116°55'2.0208" | N16: 1 | O16: 2500 | P16: =Table14[[#This Row],[14]]*Table14[[#This Row],[15]] -> 2500 | Q16: PLTU | R16: UTAMA DAN CADANGAN
A17: =IF($C17<>"", SUBTOTAL(103,$C$6:C17), "") | B17: =B16 -> 5 | K17: =IF($E17="IUPTLS",IF(ISBLANK(J17), " ", DATE(YEAR(J17)+5,MONTH(J17),DAY(J17))),IF($E17="SKTP","","")) | N17: 2 | O17: 635 | P17: =Table14[[#This Row],[14]]*Table14[[#This Row],[15]] -> 1270 | Q17: PLTD
A18: =IF($C18<>"", SUBTOTAL(103,$C$6:C18), "") | B18: =B17 -> 5 | K18: =IF($E18="IUPTLS",IF(ISBLANK(J18), " ", DATE(YEAR(J18)+5,MONTH(J18),DAY(J18))),IF($E18="SKTP","","")) | N18: 1 | O18: 250 | P18: =Table14[[#This Row],[14]]*Table14[[#This Row],[15]] -> 250 | Q18: PLTD
A19: =IF($C19<>"", SUBTOTAL(103,$C$6:C19), "") -> 6 | B19: 6 | C19: PT. MULTI HARAPAN UTAMA | E19: IUPTLS | F19: I-202204201228496728117 | G19: 671.12/1031/I-KTL/2022 | H19: 44741 | I19: 812021103223900100001 | J19: 44775 | K19: =IF($E19="IUPTLS",IF(ISBLANK(J19), " ", DATE(YEAR(J19)+5,MONTH(J19),DAY(J19))),IF($E19="SKTP","","")) -> 46601 | L19: Desa Loa Kulu Kota, Kecamatan Loa Kulu, Kabupaten Kutai Kartanegara | M19: S : 0°32'13.03" T : 117°1'51.39" | N19: 1 | O19: 1000 | P19: =Table14[[#This Row],[14]]*Table14[[#This Row],[15]] -> 1000 | Q19: PLTD | R19: UTAMA DAN DARURAT
A20: =IF($C20<>"", SUBTOTAL(103,$C$6:C20), "") | B20: =B19 -> 6 | K20: =IF($E20="IUPTLS",IF(ISBLANK(J20), " ", DATE(YEAR(J20)+5,MONTH(J20),DAY(J20))),IF($E20="SKTP","","")) | N20: 1 | O20: 270 | P20: =Table14[[#This Row],[14]]*Table14[[#This Row],[15]] -> 270 | Q20: PLTD
A21: =IF($C21<>"", SUBTOTAL(103,$C$6:C21), "") | B21: =B20 -> 6 | K21: =IF($E21="IUPTLS",IF(ISBLANK(J21), " ", DATE(YEAR(J21)+5,MONTH(J21),DAY(J21))),IF($E21="SKTP","","")) | N21: 1 | O21: 300 | P21: =Table14[[#This Row],[14]]*Table14[[#This Row],[15]] -> 300 | Q21: PLTD
A22: =IF($C22<>"", SUBTOTAL(103,$C$6:C22), "") | B22: =B21 -> 6 | K22: =IF($E22="IUPTLS",IF(ISBLANK(J22), " ", DATE(YEAR(J22)+5,MONTH(J22),DAY(J22))),IF($E22="SKTP","","")) | M22: S : 0°32'10.07" T : 117°1'34.98" | N22: 1 | O22: 110 | P22: =Table14[[#This Row],[14]]*Table14[[#This Row],[15]] -> 110 | Q22: PLTD
A23: =IF($C23<>"", SUBTOTAL(103,$C$6:C23), "") | B23: =B22 -> 6 | K23: =IF($E23="IUPTLS",IF(ISBLANK(J23), " ", DATE(YEAR(J23)+5,MONTH(J23),DAY(J23))),IF($E23="SKTP","","")) | N23: 1 | O23: 500 | P23: =Table14[[#This Row],[14]]*Table14[[#This Row],[15]] -> 500 | Q23: PLTD
A24: =IF($C24<>"", SUBTOTAL(103,$C$6:C24), "") | B24: =B23 -> 6 | K24: =IF($E24="IUPTLS",IF(ISBLANK(J24), " ", DATE(YEAR(J24)+5,MONTH(J24),DAY(J24))),IF($E24="SKTP","","")) | M24: S : 0°33'41.47" T : 117°1'32.29" | N24: 1 | O24: 500 | P24: =Table14[[#This Row],[14]]*Table14[[#This Row],[15]] -> 500 | Q24: PLTD
A25: =IF($C25<>"", SUBTOTAL(103,$C$6:C25), "") -> 7 | B25: 7 | C25: PT. MULTI HARAPAN UTAMA | E25: IUPTLS | F25: I-202206171446179539669 | G25: 671.12/1167/I-KTL/2022 | H25: 44767 | I25: 812021103223900100002 | J25: 44775 | K25: =IF($E25="IUPTLS",IF(ISBLANK(J25), " ", DATE(YEAR(J25)+5,MONTH(J25),DAY(J25))),IF($E25="SKTP","","")) -> 46601 | L25: Desa Loa Kulu Kota, Kecamatan Loa Kulu, Kabupaten Kutai Kartanegara | M25: S : 0°32'6.68" T : 117°1'39.2" | N25: 5 | O25: 250 | P25: =Table14[[#This Row],[14]]*Table14[[#This Row],[15]]&" kW" -> 1250 kW | Q25: PLTS | R25: CADANGAN
A26: =IF($C26<>"", SUBTOTAL(103,$C$6:C26), "") | B26: =B25 -> 7 | K26: =IF($E26="IUPTLS",IF(ISBLANK(J26), " ", DATE(YEAR(J26)+5,MONTH(J26),DAY(J26))),IF($E26="SKTP","","")) | N26: 2800 | O26: 0.46 | P26: =Table14[[#This Row],[14]]*Table14[[#This Row],[15]] -> 1288 | Q26: PLTS
A27: =IF($C27<>"", SUBTOTAL(103,$C$6:C27), "") -> 8 | B27: 8 | C27: PT. PAMAPERSADA NUSANTARA (PAMA BAYA) | E27: IUPTLS | F27: I-20220161139108339600 | G27: 671.12/1190/I-KTL/2022 | H27: 44771 | I27: 812021106038900470071 | J27: 44791 | K27: =IF($E27="IUPTLS",IF(ISBLANK(J27), " ", DATE(YEAR(J27)+5,MONTH(J27),DAY(J27))),IF($E27="SKTP","","")) -> 46617 | L27: Desa Bhuana Jaya, Kecamatan Tenggarong Seberang, Kabupaten Kutai Kartanegara | N27: 5 | O27: 500 | P27: =Table14[[#This Row],[14]]*Table14[[#This Row],[15]] -> 2500 | Q27: PLTD | R27: UTAMA
A28: =IF($C28<>"", SUBTOTAL(103,$C$6:C28), "") | B28: =B27 -> 8 | K28: =IF($E28="IUPTLS",IF(ISBLANK(J28), " ", DATE(YEAR(J28)+5,MONTH(J28),DAY(J28))),IF($E28="SKTP","","")) | N28: 3 | O28: 380 | P28: =Table14[[#This Row],[14]]*Table14[[#This Row],[15]] -> 1140 | Q28: PLTD | R28: UTAMA
A29: =IF($C29<>"", SUBTOTAL(103,$C$6:C29), "") -> 9 | B29: 9 | C29: PT. PAMAPERSADA NUSANTARA (PAMA INDO) | E29: IUPTLS | F29: I-202209191717156974356 | G29: 671.12/1747/I-KTL/2022 | H29: 44862 | I29: 812021106038900490076 | J29: 44876 | K29: =IF($E29="IUPTLS",IF(ISBLANK(J29), " ", DATE(YEAR(J29)+5,MONTH(J29),DAY(J29))),IF($E29="SKTP","","")) -> 46702 | L29: Desa Sukrahmat, Kecamatan Teluk Pandan, Kabupaten Kutai Timur | M29: U : 0°9’11.11” T : 117°17’41.13” | N29: 2 | O29: 550 | P29: =Table14[[#This Row],[14]]*Table14[[#This Row],[15]] -> 1100 | Q29: PLTD | R29: UTAMA | S29: Dalam 1 Rekomtek, lokasi pembangkit ada pada 2 kabupaten
A30: =IF($C30<>"", SUBTOTAL(103,$C$6:C30), "") | B30: =B29 -> 9 | K30: =IF($E30="IUPTLS",IF(ISBLANK(J30), " ", DATE(YEAR(J30)+5,MONTH(J30),DAY(J30))),IF($E30="SKTP","","")) | M30: U : 0°9’1.58” T : 117°17’43.69” | N30: 2 | O30: 380 | P30: =Table14[[#This Row],[14]]*Table14[[#This Row],[15]] -> 760 | Q30: PLTD | R30: UTAMA
A31: =IF($C31<>"", SUBTOTAL(103,$C$6:C31), "") | B31: =B30 -> 9 | K31: =IF($E31="IUPTLS",IF(ISBLANK(J31), " ", DATE(YEAR(J31)+5,MONTH(J31),DAY(J31))),IF($E31="SKTP","","")) | M31: U : 0°8’54.75” T : 117°17’16.81” | N31: 2 | O31: 500 | P31: =Table14[[#This Row],[14]]*Table14[[#This Row],[15]] -> 1000 | Q31: PLTD | R31: UTAMA
A32: =IF($C32<>"", SUBTOTAL(103,$C$6:C32), "") | B32: =B31 -> 9 | K32: =IF($E32="IUPTLS",IF(ISBLANK(J32), " ", DATE(YEAR(J32)+5,MONTH(J32),DAY(J32))),IF($E32="SKTP","","")) | N32: 1 | O32: 550 | P32: =Table14[[#This Row],[14]]*Table14[[#This Row],[15]] -> 550 | Q32: PLTD | R32: UTAMA
A33: =IF($C33<>"", SUBTOTAL(103,$C$6:C33), "") | B33: =B32 -> 9 | K33: =IF($E33="IUPTLS",IF(ISBLANK(J33), " ", DATE(YEAR(J33)+5,MONTH(J33),DAY(J33))),IF($E33="SKTP","","")) | M33: U : 0°7’26.1” T : 117°22’4.21” | N33: 1 | O33: 500 | P33: =Table14[[#This Row],[14]]*Table14[[#This Row],[15]] -> 500 | Q33: PLTD | R33: UTAMA
A34: =IF($C34<>"", SUBTOTAL(103,$C$6:C34), "") | B34: =B33 -> 9 | K34: =IF($E34="IUPTLS",IF(ISBLANK(J34), " ", DATE(YEAR(J34)+5,MONTH(J34),DAY(J34))),IF($E34="SKTP","","")) | N34: 2 | O34: 380 | P34: =Table14[[#This Row],[14]]*Table14[[#This Row],[15]] -> 760 | Q34: PLTD | R34: UTAMA
A35: =IF($C35<>"", SUBTOTAL(103,$C$6:C35), "") | B35: =B34 -> 9 | K35: =IF($E35="IUPTLS",IF(ISBLANK(J35), " ", DATE(YEAR(J35)+5,MONTH(J35),DAY(J35))),IF($E35="SKTP","","")) | L35: Desa Santan Tengah, Kecamatan Marangkayu, Kabupaten Kutai Kartanegara | M35: U : 0°1’9.48” T : 117°28’17.28” | N35: 1 | O35: 500 | P35: =Table14[[#This Row],[14]]*Table14[[#This Row],[15]] -> 500 | Q35: PLTD | R35: UTAMA
A36: =IF($C36<>"", SUBTOTAL(103,$C$6:C36), "") | B36: =B35 -> 9 | K36: =IF($E36="IUPTLS",IF(ISBLANK(J36), " ", DATE(YEAR(J36)+5,MONTH(J36),DAY(J36))),IF($E36="SKTP","","")) | N36: 1 | O36: 380 | P36: =Table14[[#This Row],[14]]*Table14[[#This Row],[15]] -> 380 | Q36: PLTD | R36: UTAMA
A37: =IF($C37<>"", SUBTOTAL(103,$C$6:C37), "") -> 10 | B37: 10 | C37: PT. NIAGAMAS GEMILANG | E37: IUPTLS | F37: I-202209191257565294104 | G37: 671.12/1841/I-KTL/2022 | H37: 44874 | I37: 812021704099400060001 | J37: 44879 | K37: =IF($E37="IUPTLS",IF(ISBLANK(J37), " ", DATE(YEAR(J37)+5,MONTH(J37),DAY(J37))),IF($E37="SKTP","","")) -> 46705 | L37: Sungai Tantai RT. 005, Dusun 1 Sentuk, Desa Sungai Payang, Kecamatan Loa Kulu, Kabupaten Kutai Kartanegara | M37: S : 0°37’48,63” T : 116°49’34,03” | N37: 2 | O37: 30 | P37: =Table14[[#This Row],[14]]*Table14[[#This Row],[15]] -> 60 | Q37: PLTD | R37: UTAMA
A38: =IF($C38<>"", SUBTOTAL(103,$C$6:C38), "") | B38: =B37 -> 10 | K38: =IF($E38="IUPTLS",IF(ISBLANK(J38), " ", DATE(YEAR(J38)+5,MONTH(J38),DAY(J38))),IF($E38="SKTP","","")) | M38: S : 0°35’39,62” T : 116°49’21,06” | N38: 1 | O38: 3200 | P38: =Table14[[#This Row],[14]]*Table14[[#This Row],[15]] -> 3200 | Q38: PLTU | R38: UTAMA
A39: =IF($C39<>"", SUBTOTAL(103,$C$6:C39), "") | B39: =B38 -> 10 | K39: =IF($E39="IUPTLS",IF(ISBLANK(J39), " ", DATE(YEAR(J39)+5,MONTH(J39),DAY(J39))),IF($E39="SKTP","","")) | N39: 2 | O39: 670 | P39: =Table14[[#This Row],[14]]*Table14[[#This Row],[15]] -> 1340 | Q39: PLTD | R39: UTAMA
A40: =IF($C40<>"", SUBTOTAL(103,$C$6:C40), "") | B40: =B39 -> 10 | K40: =IF($E40="IUPTLS",IF(ISBLANK(J40), " ", DATE(YEAR(J40)+5,MONTH(J40),DAY(J40))),IF($E40="SKTP","","")) | N40: 1 | O40: 400 | P40: =Table14[[#This Row],[14]]*Table14[[#This Row],[15]] -> 400 | Q40: PLTD | R40: UTAMA
A41: =IF($C41<>"", SUBTOTAL(103,$C$6:C41), "") -> 11 | B41: 11 | C41: PT. PAMAPERSADA INDONESIA (PAMA ABKL) | E41: IUPTLS | F41: I-202209151048079229439 | G41: 671.12/1843/I-KTL/2022 | H41: 44874 | I41: 812021106038900490077 | J41: 44879 | K41: =IF($E41="IUPTLS",IF(ISBLANK(J41), " ", DATE(YEAR(J41)+5,MONTH(J41),DAY(J41))),IF($E41="SKTP","","")) -> 46705 | L41: Desa Purwajaya, Kecamatan Loa Janan, Kabupaten Kutai Kartanegara | M41: S : 0°30’38,85” T : 117°4’9,78” | N41: 2 | O41: 380 | P41: =Table14[[#This Row],[14]]*Table14[[#This Row],[15]] -> 760 | Q41: PLTD | R41: UTAMA DAN DARURAT
...

Sheet KUTIM
A1: DAFTAR REKOMTEK/PERTEK PERIZINAN/NON PERIZINAN USAHA PENYEDIAAN TENAGA LISTRIK UNTUK KEPENTINGAN SENDIRI TAHUN 2022 KABUPATEN KUTAI TIMUR
A3: No. | B3: ID | C3: Data Pemohon/Pelaku Usaha | E3: Data Perizinan/Non Perizinan | L3: Data Pembangkit Listrik | S3: Catatan
C4: Nama | D4: Kontak | E4: Jenis | F4: No. Pengajuan | G4: No. Surat Keluar (Rekomtek/Pertek) | H4: Tanggal | I4: No. Surat Izin Terbit | J4: Tanggal Terbit | K4: Tanggal Akhir | L4: Lokasi | M4: Titik Koordinat | N4: Jumlah | O4: Kapasitas | P4: Total Kapasitas (kVA) | Q4: Jenis | R4: Sifat Penggunaan
A5: 1 | B5: 2 | C5: 3 | D5: 4 | E5: 5 | F5: 6 | G5: 7 | H5: 8 | I5: 9 | J5: 10 | K5: 11 | L5: 12 | M5: 13 | N5: 14 | O5: 15 | P5: 16 (14*15) | Q5: 17 | R5: 18 | S5: 19
A6: =IF($C6<>"", SUBTOTAL(103,$C$6:C6), "") -> 1 | B6: 1 | C6: PT. PADMA WINATA THANI (Q-Hotel Sangatta) | E6: SKTP | F6: 503/238/DPMPTSP-IV/II/2022; 2403A8 | G6: 671.12/450/I-KTL/2022 | H6: 44622 | I6: 503/0156/SKTP/DPMPTSP/III/2022 | J6: 44634 | K6: =IF($E6="IUPTLS",IF(ISBLANK(J6), " ", DATE(YEAR(J6)+5,MONTH(J6),DAY(J6))),IF($E6="SKTP","","")) | L6: Desa Sangatta Utara, Kecamatan Sangatta Utara, Kabupaten Kutai Timur | N6: 1 | O6: 200 | P6: =Table145[[#This Row],[14]]*Table145[[#This Row],[15]] -> 200 | Q6: PLTD | R6: DARURAT
A7: =IF($C7<>"", SUBTOTAL(103,$C$6:C7), "") | B7: =B6 -> 1 | K7: =IF($E7="IUPTLS",IF(ISBLANK(J7), " ", DATE(YEAR(J7)+5,MONTH(J7),DAY(J7))),IF($E7="SKTP","","")) | N7: 1 | O7: 250 | P7: =Table145[[#This Row],[14]]*Table145[[#This Row],[15]] -> 250 | Q7: PLTD | R7: DARURAT
A8: =IF($C8<>"", SUBTOTAL(103,$C$6:C8), "") -> 2 | B8: 2 | C8: PT. WIDYA SAPTA CONTRACTOR | E8: IUPTLS | F8: i-20220321316319326899 | G8: 671.12/585/I-KTL/2022 | H8: 44642 | I8: 812031502156200180001 | J8: 44649 | K8: =IF($E8="IUPTLS",IF(ISBLANK(J8), " ", DATE(YEAR(J8)+5,MONTH(J8),DAY(J8))),IF($E8="SKTP","","")) -> 46475 | L8: Desa Bukit Makmur, Kecamatan Kaliorang, Kabupaten Kutai Timur | N8: 1 | O8: 27.5 | P8: =Table145[[#This Row],[14]]*Table145[[#This Row],[15]] -> 27.5 | Q8: PLTD | R8: UTAMA DAN CADANGAN
A9: =IF($C9<>"", SUBTOTAL(103,$C$6:C9), "") | B9: =B8 -> 2 | K9: =IF($E9="IUPTLS",IF(ISBLANK(J9), " ", DATE(YEAR(J9)+5,MONTH(J9),DAY(J9))),IF($E9="SKTP","","")) | N9: 1 | O9: 60 | P9: =Table145[[#This Row],[14]]*Table145[[#This Row],[15]] -> 60 | Q9: PLTD
A10: =IF($C10<>"", SUBTOTAL(103,$C$6:C10), "") | B10: =B9 -> 2 | K10: =IF($E10="IUPTLS",IF(ISBLANK(J10), " ", DATE(YEAR(J10)+5,MONTH(J10),DAY(J10))),IF($E10="SKTP","","")) | N10: 1 | O10: 200 | P10: =Table145[[#This Row],[14]]*Table145[[#This Row],[15]] -> 200 | Q10: PLTD
A11: =IF($C11<>"", SUBTOTAL(103,$C$6:C11), "") | B11: =B10 -> 2 | K11: =IF($E11="IUPTLS",IF(ISBLANK(J11), " ", DATE(YEAR(J11)+5,MONTH(J11),DAY(J11))),IF($E11="SKTP","","")) | N11: 1 | O11: 500 | P11: =Table145[[#This Row],[14]]*Table145[[#This Row],[15]] -> 500 | Q11: PLTD
A12: =IF($C12<>"", SUBTOTAL(103,$C$6:C12), "") -> 3 | B12: 3 | C12: PT. KOBEXINDO CEMENT | E12: SKTP | F12: 503/454/DPMPTSP-IV/III/2022; AFE36D | G12: 671.12/1010/I-KTL/2022 | H12: 44739 | I12: 503/0252/SKTP/DPMPTSP/VII/2022 | J12: 44753 | K12: =IF($E12="IUPTLS",IF(ISBLANK(J12), " ", DATE(YEAR(J12)+5,MONTH(J12),DAY(J12))),IF($E12="SKTP","","")) | L12: Desa Selangkau, Kecamatan Kaliorang, Kabupaten Kutai timur | M12: U : 0°48'4.37" T : 117°48'37.93" | N12: 1 | O12: 220 | P12: =Table145[[#This Row],[14]]*Table145[[#This Row],[15]] -> 220 | Q12: PLTD | R12: UTAMA
A13: =IF($C13<>"", SUBTOTAL(103,$C$6:C13), "") -> 4 | B13: 4 | C13: PT. KOBEXINDO CEMENT | E13: IUPTLS | F13: I-202204230840471394124 | G13: 671.12/1012/I-KTL/2022 | H13: 44739 | I13: 912010374172500000001 | J13: 44750 | K13: =IF($E13="IUPTLS",IF(ISBLANK(J13), " ", DATE(YEAR(J13)+5,MONTH(J13),DAY(J13))),IF($E13="SKTP","","")) -> 46576 | L13: Desa Selangkau, Kecamatan Kaliorang, Kabupaten Kutai timur | M13: U : 0°47'42.83" T : 117°48'22.94" | N13: 2 | O13: 1050 | P13: =Table145[[#This Row],[14]]*Table145[[#This Row],[15]] -> 2100 | Q13: PLTD | R13: UTAMA
A14: =IF($C14<>"", SUBTOTAL(103,$C$6:C14), "") | B14: =B13 -> 4 | K14: =IF($E14="IUPTLS",IF(ISBLANK(J14), " ", DATE(YEAR(J14)+5,MONTH(J14),DAY(J14))),IF($E14="SKTP","","")) | N14: 1 | O14: 220 | P14: =Table145[[#This Row],[14]]*Table145[[#This Row],[15]] -> 220 | Q14: PLTD | R14: UTAMA
A15: =IF($C15<>"", SUBTOTAL(103,$C$6:C15), "") -> 5 | B15: 5 | C15: PT. PAMAPERSADA NUSANTARA (PAMA INDO) | E15: IUPTLS | F15: I-202209191717156974356 | G15: 671.12/1747/I-KTL/2022 | H15: 44862 | I15: 812021106038900490076 | J15: 44876 | K15: =IF($E15="IUPTLS",IF(ISBLANK(J15), " ", DATE(YEAR(J15)+5,MONTH(J15),DAY(J15))),IF($E15="SKTP","","")) -> 46702 | L15: Desa Sukrahmat, Kecamatan Teluk Pandan, Kabupaten Kutai Timur | M15: U : 0°9’11.11” T : 117°17’41.13” | N15: 2 | O15: 550 | P15: =Table145[[#This Row],[14]]*Table145[[#This Row],[15]] -> 1100 | Q15: PLTD | R15: UTAMA
A16: =IF($C16<>"", SUBTOTAL(103,$C$6:C16), "") | B16: =B15 -> 5 | K16: =IF($E16="IUPTLS",IF(ISBLANK(J16), " ", DATE(YEAR(J16)+5,MONTH(J16),DAY(J16))),IF($E16="SKTP","","")) | M16: U : 0°9’1.58” T : 117°17’43.69” | N16: 2 | O16: 380 | P16: =Table145[[#This Row],[14]]*Table145[[#This Row],[15]] -> 760 | Q16: PLTD | R16: UTAMA
A17: =IF($C17<>"", SUBTOTAL(103,$C$6:C17), "") | B17: =B16 -> 5 | K17: =IF($E17="IUPTLS",IF(ISBLANK(J17), " ", DATE(YEAR(J17)+5,MONTH(J17),DAY(J17))),IF($E17="SKTP","","")) | M17: U : 0°8’54.75” T : 117°17’16.81” | N17: 2 | O17: 500 | P17: =Table145[[#This Row],[14]]*Table145[[#This Row],[15]] -> 1000 | Q17: PLTD | R17: UTAMA
A18: =IF($C18<>"", SUBTOTAL(103,$C$6:C18), "") | B18: =B17 -> 5 | K18: =IF($E18="IUPTLS",IF(ISBLANK(J18), " ", DATE(YEAR(J18)+5,MONTH(J18),DAY(J18))),IF($E18="SKTP","","")) | N18: 1 | O18: 550 | P18: =Table145[[#This Row],[14]]*Table145[[#This Row],[15]] -> 550 | Q18: PLTD | R18: UTAMA
A19: =IF($C19<>"", SUBTOTAL(103,$C$6:C19), "") | B19: =B18 -> 5 | K19: =IF($E19="IUPTLS",IF(ISBLANK(J19), " ", DATE(YEAR(J19)+5,MONTH(J19),DAY(J19))),IF($E19="SKTP","","")) | M19: U : 0°7’26.1” T : 117°22’4.21” | N19: 1 | O19: 500 | P19: =Table145[[#This Row],[14]]*Table145[[#This Row],[15]] -> 500 | Q19: PLTD | R19: UTAMA
A20: =IF($C20<>"", SUBTOTAL(103,$C$6:C20), "") | B20: =B19 -> 5 | K20: =IF($E20="IUPTLS",IF(ISBLANK(J20), " ", DATE(YEAR(J20)+5,MONTH(J20),DAY(J20))),IF($E20="SKTP","","")) | N20: 2 | O20: 380 | P20: =Table145[[#This Row],[14]]*Table145[[#This Row],[15]] -> 760 | Q20: PLTD | R20: UTAMA
A21: =IF($C21<>"", SUBTOTAL(103,$C$6:C21), "") | B21: =B20 -> 5 | K21: =IF($E21="IUPTLS",IF(ISBLANK(J21), " ", DATE(YEAR(J21)+5,MONTH(J21),DAY(J21))),IF($E21="SKTP","","")) | L21: Desa Santan Tengah, Kecamatan Marangkayu, Kabupaten Kutai Kartanegara | M21: U : 0°1’9.48” T : 117°28’17.28” | N21: 1 | O21: 500 | P21: =Table145[[#This Row],[14]]*Table145[[#This Row],[15]] -> 500 | Q21: PLTD | R21: UTAMA | S21: Dalam 1 Rekomtek, lokasi pembangkit ada pada 2 kabupaten
A22: =IF($C22<>"", SUBTOTAL(103,$C$6:C22), "") | B22: =B21 -> 5 | K22: =IF($E22="IUPTLS",IF(ISBLANK(J22), " ", DATE(YEAR(J22)+5,MONTH(J22),DAY(J22))),IF($E22="SKTP","","")) | N22: 1 | O22: 380 | P22: =Table145[[#This Row],[14]]*Table145[[#This Row],[15]] -> 380 | Q22: PLTD | R22: UTAMA
A23: =IF($C23<>"", SUBTOTAL(103,$C$6:C23), "") -> 6 | B23: 6 | C23: PT. PAMAPERSADA NUSANTARA (PAMA KPCB) | E23: SKTP | F23: 917AC1 | G23: 671.12/2270/I-KTL/2022 | H23: 44921 | I23: 503/0432/SKTP/DPMPTSP/XII/2022 | J23: 44925 | K23: =IF($E23="IUPTLS",IF(ISBLANK(J23), " ", DATE(YEAR(J23)+5,MONTH(J23),DAY(J23))),IF($E23="SKTP","","")) | L23: Desa Sepaso Timur, Kecamatan Sangatta Utara, Kabupaten Kutai Timur | M23: U : 0°47’3.8”, T : 117°31’20.24” | N23: 1 | O23: 500 | P23: =Table145[[#This Row],[14]]*Table145[[#This Row],[15]] -> 500 | Q23: PLTD | R23: UTAMA
A24: =IF($C24<>"", SUBTOTAL(103,$C$6:C24), "") -> 7 | B24: 7 | C24: PT. THIESS CONTRACTORS INDONESIA Site Sangatta Project | E24: SKTP | F24: 712E29 | G24: 671.12/2271/I-KTL/2022 | H24: 44921 | I24: 503/0430/SKTP/DPMPTSP/XII/2022 | J24: 44925 | K24: =IF($E24="IUPTLS",IF(ISBLANK(J24), " ", DATE(YEAR(J24)+5,MONTH(J24),DAY(J24))),IF($E24="SKTP","","")) | L24: Desa Swargabara, Kecamatan Sangatta Utara, Kabupaten Kutai Timur | M24: U : 0°32’7.3”, T : 117°31’5.56” | N24: 1 | O24: 200 | P24: =Table145[[#This Row],[14]]*Table145[[#This Row],[15]] -> 200 | Q24: PLTD | R24: UTAMA
A25: =IF($C25<>"", SUBTOTAL(103,$C$6:C25), "") -> 8 | B25: 8 | C25: PT. THIESS CONTRACTORS INDONESIA Site Sangatta Project | E25: IUPTLS | F25: I-202211300936586981458 | G25: 671.12/2276/I-KTL/2022 | H25: 44921 | I25: 912040618127200090006 | J25: 44942 | K25: =IF($E25="IUPTLS",IF(ISBLANK(J25), " ", DATE(YEAR(J25)+5,MONTH(J25),DAY(J25))),IF($E25="SKTP","","")) -> 46768 | L25: Desa Swargabara, Kecamatan Sangatta Utara, Kabupaten Kutai Timur | M25: U : 0°36’8.57”, T : 117°25’24.94” | N25: 2 | O25: 365 | P25: =Table145[[#This Row],[14]]*Table145[[#This Row],[15]] -> 730 | Q25: PLTD | R25: UTAMA
A26: =IF($C26<>"", SUBTOTAL(103,$C$6:C26), "") | B26: =B25 -> 8 | K26: =IF($E26="IUPTLS",IF(ISBLANK(J26), " ", DATE(YEAR(J26)+5,MONTH(J26),DAY(J26))),IF($E26="SKTP","","")) | N26: 1 | O26: 275 | P26: =Table145[[#This Row],[14]]*Table145[[#This Row],[15]] -> 275 | Q26: PLTD | R26: UTAMA
A27: =IF($C27<>"", SUBTOTAL(103,$C$6:C27), "") | B27: =B26 -> 8 | K27: =IF($E27="IUPTLS",IF(ISBLANK(J27), " ", DATE(YEAR(J27)+5,MONTH(J27),DAY(J27))),IF($E27="SKTP","","")) | M27: U : 0°33’9.94”, T : 117°28’39.88” | N27: 1 | O27: 275 | P27: =Table145[[#This Row],[14]]*Table145[[#This Row],[15]] -> 275 | Q27: PLTD | R27: UTAMA
A28: =IF($C28<>"", SUBTOTAL(103,$C$6:C28), "") | B28: =B27 -> 8 | K28: =IF($E28="IUPTLS",IF(ISBLANK(J28), " ", DATE(YEAR(J28)+5,MONTH(J28),DAY(J28))),IF($E28="SKTP","","")) | M28: U : 0°36’10.82”, T : 117°25’10.29” | N28: 1 | O28: 275 | P28: =Table145[[#This Row],[14]]*Table145[[#This Row],[15]] -> 275 | Q28: PLTD | R28: UTAMA
G31: Jumlah Rekomtek IUPTLS | H31: =COUNTIF($E$6:$E$28,"IUPTLS") -> 4 | N31: Total Kapasitas (kVA) | P31: =SUM($P$6:$P$28)-SUM(P21:P22) -> 10702.5
G32: Jumlah Pertek SKTP | H32: =COUNTIF($E$6:$E$28,"SKTP") -> 4
G33: Jumlah Total | H33: =SUM(H31:H32) -> 8

Sheet KUBAR
A1: DAFTAR REKOMTEK/PERTEK PERIZINAN/NON PERIZINAN USAHA PENYEDIAAN TENAGA LISTRIK UNTUK KEPENTINGAN SENDIRI TAHUN 2022 KABUPATEN KUTAI BARAT
A3: No. | B3: ID | C3: Data Pemohon/Pelaku Usaha | E3: Data Perizinan/Non Perizinan | L3: Data Pembangkit Listrik | S3: Catatan
C4: Nama | D4: Kontak | E4: Jenis | F4: No. Pengajuan | G4: No. Surat Keluar (Rekomtek/Pertek) | H4: Tanggal | I4: No. Surat Izin Terbit | J4: Tanggal Terbit | K4: Tanggal Akhir | L4: Lokasi | M4: Titik Koordinat | N4: Jumlah | O4: Kapasitas | P4: Total Kapasitas (kVA) | Q4: Jenis | R4: Sifat Penggunaan
A5: 1 | B5: 2 | C5: 3 | D5: 4 | E5: 5 | F5: 6 | G5: 7 | H5: 8 | I5: 9 | J5: 10 | K5: 11 | L5: 12 | M5: 13 | N5: 14 | O5: 15 | P5: 16 (14*15) | Q5: 17 | R5: 18 | S5: 19
A6: =IF($C6<>"", SUBTOTAL(103,$C$6:C6), "") -> 1 | B6: 1 | C6: PT. AGRO MANUNGGAL SELARAS | E6: IUPTLS | F6: I-202206031100379334133 | G6: 671.12/1014/I-KTL/2022 | H6: 44739 | I6: 912020613361200000001 | J6: 44760 | K6: =IF($E6="IUPTLS",IF(ISBLANK(J6), " ", DATE(YEAR(J6)+5,MONTH(J6),DAY(J6))),IF($E6="SKTP","","")) -> 46586 | L6: Desa Jelmu Sibak, Kecamatan Bentian Besar, Kabupaten Kutai Barat | M6: S : 0°53'29.058" T : 115°47'48.654" | N6: 1 | O6: 2500 | P6: =Table1456[[#This Row],[14]]*Table1456[[#This Row],[15]] -> 2500 | Q6: PLTU | R6: UTAMA DAN CADANGAN
A7: =IF($C7<>"", SUBTOTAL(103,$C$6:C7), "") | B7: =B6 -> 1 | K7: =IF($E7="IUPTLS",IF(ISBLANK(J7), " ", DATE(YEAR(J7)+5,MONTH(J7),DAY(J7))),IF($E7="SKTP","","")) | N7: 3 | O7: 500 | P7: =Table1456[[#This Row],[14]]*Table1456[[#This Row],[15]] -> 1500 | Q7: PLTD
A8: =IF($C8<>"", SUBTOTAL(103,$C$6:C8), "") | B8: =B7 -> 1 | K8: =IF($E8="IUPTLS",IF(ISBLANK(J8), " ", DATE(YEAR(J8)+5,MONTH(J8),DAY(J8))),IF($E8="SKTP","","")) | N8: 1 | O8: 90 | P8: =Table1456[[#This Row],[14]]*Table1456[[#This Row],[15]] -> 90 | Q8: PLTD
A9: =IF($C9<>"", SUBTOTAL(103,$C$6:C9), "") -> 2 | B9: 2 | C9: PT. PUTRA BONGAN JAYA | E9: IUPTLS | F9: I-202210101107523904960 | G9: 671.12/1998/I-KTL/2022 | H9: 44890 | I9: 812021511246100010001 | J9: 44896 | K9: =IF($E9="IUPTLS",IF(ISBLANK(J9), " ", DATE(YEAR(J9)+5,MONTH(J9),DAY(J9))),IF($E9="SKTP","","")) -> 46722 | L9: Desa Muara Gusik, Kecamatan Bongan, Kabupaten Kutai Barat | N9: 1 | O9: 2500 | P9: =Table1456[[#This Row],[14]]*Table1456[[#This Row],[15]] -> 2500 | Q9: PLTU | R9: UTAMA
A10: =IF($C10<>"", SUBTOTAL(103,$C$6:C10), "") | B10: =B9 -> 2 | K10: =IF($E10="IUPTLS",IF(ISBLANK(J10), " ", DATE(YEAR(J10)+5,MONTH(J10),DAY(J10))),IF($E10="SKTP","","")) | N10: 1 | O10: 400 | P10: =Table1456[[#This Row],[14]]*Table1456[[#This Row],[15]] -> 400 | Q10: PLTD | R10: UTAMA
A11: =IF($C11<>"", SUBTOTAL(103,$C$6:C11), "") | B11: =B10 -> 2 | K11: =IF($E11="IUPTLS",IF(ISBLANK(J11), " ", DATE(YEAR(J11)+5,MONTH(J11),DAY(J11))),IF($E11="SKTP","","")) | N11: 1 | O11: 770 | P11: =Table1456[[#This Row],[14]]*Table1456[[#This Row],[15]] -> 770 | Q11: PLTD | R11: UTAMA
A12: =IF($C12<>"", SUBTOTAL(103,$C$6:C12), "") -> 3 | B12: 3 | C12: PT. KALIMANTAN AGRO MAKMUR | E12: IUPTLS | F12: I-202210281131428692951 | G12: 671.12/1999/I-KTL/2022 | H12: 44890 | I12: 912010717058200050001 | J12: 44896 | K12: =IF($E12="IUPTLS",IF(ISBLANK(J12), " ", DATE(YEAR(J12)+5,MONTH(J12),DAY(J12))),IF($E12="SKTP","","")) -> 46722 | L12: Desa Abit, Kecamatan Mook Manaar Bulatn, Kabupaten Kutai Barat | M12: S : 0°12’23.09” T : 115°59’3.92” | N12: 1 | O12: 2135 | P12: =Table1456[[#This Row],[14]]*Table1456[[#This Row],[15]] -> 2135 | Q12: PLTU | R12: UTAMA
A13: =IF($C13<>"", SUBTOTAL(103,$C$6:C13), "") | B13: =B12 -> 3 | K13: =IF($E13="IUPTLS",IF(ISBLANK(J13), " ", DATE(YEAR(J13)+5,MONTH(J13),DAY(J13))),IF($E13="SKTP","","")) | N13: 1 | O13: 275 | P13: =Table1456[[#This Row],[14]]*Table1456[[#This Row],[15]] -> 275 | Q13: PLTD | R13: UTAMA
A14: =IF($C14<>"", SUBTOTAL(103,$C$6:C14), "") | B14: =B13 -> 3 | K14: =IF($E14="IUPTLS",IF(ISBLANK(J14), " ", DATE(YEAR(J14)+5,MONTH(J14),DAY(J14))),IF($E14="SKTP","","")) | N14: 2 | O14: 500 | P14: =Table1456[[#This Row],[14]]*Table1456[[#This Row],[15]] -> 1000 | Q14: PLTD | R14: UTAMA
G17: Jumlah Rekomtek IUPTLS | H17: =COUNTIF($E$6:$E$14,"IUPTLS") -> 3 | N17: Total Kapasitas (kVA) | P17: =SUM($P$6:$P$14) -> 11170
G18: Jumlah Pertek SKTP | H18: =COUNTIF($E$6:$E$14,"SKTP") -> 0
G19: Jumlah Total | H19: =SUM(H17:H18) -> 3

Sheet PASER
A1: DAFTAR REKOMTEK/PERTEK PERIZINAN/NON PERIZINAN USAHA PENYEDIAAN TENAGA LISTRIK UNTUK KEPENTINGAN SENDIRI TAHUN 2022 KABUPATEN PASER
A3: No. | B3: ID | C3: Data Pemohon/Pelaku Usaha | E3: Data Perizinan/Non Perizinan | L3: Data Pembangkit Listrik | S3: Catatan
C4: Nama | D4: Kontak | E4: Jenis | F4: No. Pengajuan | G4: No. Surat Keluar (Rekomtek/Pertek) | H4: Tanggal | I4: No. Surat Izin Terbit | J4: Tanggal Terbit | K4: Tanggal Akhir | L4: Lokasi | M4: Titik Koordinat | N4: Jumlah | O4: Kapasitas | P4: Total Kapasitas (kVA) | Q4: Jenis | R4: Sifat Penggunaan
A5: 1 | B5: 2 | C5: 3 | D5: 4 | E5: 5 | F5: 6 | G5: 7 | H5: 8 | I5: 9 | J5: 10 | K5: 11 | L5: 12 | M5: 13 | N5: 14 | O5: 15 | P5: 16 (14*15) | Q5: 17 | R5: 18 | S5: 19
A6: =IF($C6<>"", SUBTOTAL(103,$C$6:C6), "") -> 1 | B6: 1 | C6: PT. AGRO INTI KENCANAMAS | E6: IUPTLS | F6: I-202205301125294311517 | G6: 671.12/1013/I-KTL/2022 | H6: 44739 | I6: 812000196077200010001 | J6: 44742 | K6: =IF($E6="IUPTLS",IF(ISBLANK(J6), " ", DATE(YEAR(J6)+5,MONTH(J6),DAY(J6))),IF($E6="SKTP","","")) -> 46568 | L6: Desa Riwang, Kecamatan Batu Engau, Kabupaten Paser | M6: S : 2°13'22" T : 116°21'21" | N6: 1 | O6: 1500 | P6: =Table14567[[#This Row],[14]]*Table14567[[#This Row],[15]] -> 1500 | Q6: PLTU | R6: UTAMA
A7: =IF($C7<>"", SUBTOTAL(103,$C$6:C7), "") -> 2 | B7: 2 | C7: PT. PRADIKSI GUNATAMA Tbk. | E7: IUPTLS | F7: I-202208020908292867859 | G7: 671.12/1483/I-KTL/2022 | H7: 44826 | I7: 812001821216900110005 | J7: 44838 | K7: =IF($E7="IUPTLS",IF(ISBLANK(J7), " ", DATE(YEAR(J7)+5,MONTH(J7),DAY(J7))),IF($E7="SKTP","","")) -> 46664 | L7: Desa Langgai, Kecamatan Batu Engau, Kabupaten Paser | M7: S : 2°10’50.53” T : 116°12’33.64” | N7: 2 | O7: 2500 | P7: =Table14567[[#This Row],[14]]*Table14567[[#This Row],[15]] -> 5000 | Q7: PLTU | R7: UTAMA DAN DARURAT
A8: =IF($C8<>"", SUBTOTAL(103,$C$6:C8), "") | B8: =B7 -> 2 | K8: =IF($E8="IUPTLS",IF(ISBLANK(J8), " ", DATE(YEAR(J8)+5,MONTH(J8),DAY(J8))),IF($E8="SKTP","","")) | N8: 2 | O8: 640 | P8: =Table14567[[#This Row],[14]]*Table14567[[#This Row],[15]] -> 1280 | Q8: PLTD
A9: =IF($C9<>"", SUBTOTAL(103,$C$6:C9), "") | B9: =B8 -> 2 | K9: =IF($E9="IUPTLS",IF(ISBLANK(J9), " ", DATE(YEAR(J9)+5,MONTH(J9),DAY(J9))),IF($E9="SKTP","","")) | N9: 1 | O9: 500 | P9: =Table14567[[#This Row],[14]]*Table14567[[#This Row],[15]] -> 500 | Q9: PLTD
A10: =IF($C10<>"", SUBTOTAL(103,$C$6:C10), "") -> 3 | B10: 3 | C10: PT. PAMAPERSADA INDONESIA (PAMA KIDE) | E10: IUPTLS | F10: I-2022091510453485444099 | G10: 671.12/1776/I-KTL/2022 | H10: 44866 | I10: 812021106038900490075 | J10: 44876 | K10: =IF($E10="IUPTLS",IF(ISBLANK(J10), " ", DATE(YEAR(J10)+5,MONTH(J10),DAY(J10))),IF($E10="SKTP","","")) -> 46702 | L10: Desa Batu Kajang, Kecamatan Batu Sopang, Kabupaten Paser | M10: S : 1°49’30.99” T : 115°54’9.26” | N10: 2 | O10: 500 | P10: =Table14567[[#This Row],[14]]*Table14567[[#This Row],[15]] -> 1000 | Q10: PLTD | R10: UTAMA
A11: =IF($C11<>"", SUBTOTAL(103,$C$6:C11), "") | B11: =B10 -> 3 | K11: =IF($E11="IUPTLS",IF(ISBLANK(J11), " ", DATE(YEAR(J11)+5,MONTH(J11),DAY(J11))),IF($E11="SKTP","","")) | N11: 1 | O11: 550 | P11: =Table14567[[#This Row],[14]]*Table14567[[#This Row],[15]] -> 550 | Q11: PLTD | R11: UTAMA
A12: =IF($C12<>"", SUBTOTAL(103,$C$6:C12), "") | B12: =B11 -> 3 | K12: =IF($E12="IUPTLS",IF(ISBLANK(J12), " ", DATE(YEAR(J12)+5,MONTH(J12),DAY(J12))),IF($E12="SKTP","","")) | M12: S : 1°55’45.36” T : 115°51’41.35” | N12: 2 | O12: 500 | P12: =Table14567[[#This Row],[14]]*Table14567[[#This Row],[15]] -> 1000 | Q12: PLTD | R12: UTAMA
A13: =IF($C13<>"", SUBTOTAL(103,$C$6:C13), "") | B13: =B12 -> 3 | K13: =IF($E13="IUPTLS",IF(ISBLANK(J13), " ", DATE(YEAR(J13)+5,MONTH(J13),DAY(J13))),IF($E13="SKTP","","")) | M13: S : 1°56’59.01” T : 115°52’9.72” | N13: 2 | O13: 500 | P13: =Table14567[[#This Row],[14]]*Table14567[[#This Row],[15]] -> 1000 | Q13: PLTD | R13: UTAMA
A14: =IF($C14<>"", SUBTOTAL(103,$C$6:C14), "") | B14: =B13 -> 3 | K14: =IF($E14="IUPTLS",IF(ISBLANK(J14), " ", DATE(YEAR(J14)+5,MONTH(J14),DAY(J14))),IF($E14="SKTP","","")) | M14: S : 1°55’35.72” T : 115°51’35.2” | N14: 1 | O14: 500 | P14: =Table14567[[#This Row],[14]]*Table14567[[#This Row],[15]] -> 500 | Q14: PLTD | R14: UTAMA
A15: =IF($C15<>"", SUBTOTAL(103,$C$6:C15), "") | B15: =B14 -> 3 | K15: =IF($E15="IUPTLS",IF(ISBLANK(J15), " ", DATE(YEAR(J15)+5,MONTH(J15),DAY(J15))),IF($E15="SKTP","","")) | M15: S : 1°54’53.44” T : 115°51’14.92” | N15: 1 | O15: 400 | P15: =Table14567[[#This Row],[14]]*Table14567[[#This Row],[15]] -> 400 | Q15: PLTD | R15: UTAMA
A16: =IF($C16<>"", SUBTOTAL(103,$C$6:C16), "") | B16: =B15 -> 3 | K16: =IF($E16="IUPTLS",IF(ISBLANK(J16), " ", DATE(YEAR(J16)+5,MONTH(J16),DAY(J16))),IF($E16="SKTP","","")) | N16: 1 | O16: 380 | P16: =Table14567[[#This Row],[14]]*Table14567[[#This Row],[15]] -> 380 | Q16: PLTD | R16: UTAMA
G19: Jumlah Rekomtek IUPTLS | H19: =COUNTIF($E$6:$E$16,"IUPTLS") -> 3 | N19: Total Kapasitas (kVA) | P19: =SUM($P$6:$P$16) -> 13110
G20: Jumlah Pertek SKTP | H20: =COUNTIF($E$6:$E$16,"SKTP") -> 0
G21: Jumlah Total | H21: =SUM(H19:H20) -> 3

Sheet PPU
A1: DAFTAR REKOMTEK/PERTEK PERIZINAN/NON PERIZINAN USAHA PENYEDIAAN TENAGA LISTRIK UNTUK KEPENTINGAN SENDIRI TAHUN 2022 KABUPATEN PENAJAM PASER UTARA
A3: No. | B3: ID | C3: Data Pemohon/Pelaku Usaha | E3: Data Perizinan/Non Perizinan | L3: Data Pembangkit Listrik | S3: Catatan
C4: Nama | D4: Kontak | E4: Jenis | F4: No. Pengajuan | G4: No. Surat Keluar (Rekomtek/Pertek) | H4: Tanggal | I4: No. Surat Izin Terbit | J4: Tanggal Terbit | K4: Tanggal Akhir | L4: Lokasi | M4: Titik Koordinat | N4: Jumlah | O4: Kapasitas | P4: Total Kapasitas (kVA) | Q4: Jenis | R4: Sifat Penggunaan
A5: 1 | B5: 2 | C5: 3 | D5: 4 | E5: 5 | F5: 6 | G5: 7 | H5: 8 | I5: 9 | J5: 10 | K5: 11 | L5: 12 | M5: 13 | N5: 14 | O5: 15 | P5: 16 (14*15) | Q5: 17 | R5: 18 | S5: 19
